Workbook

Sheet Import Games

Sheet Today's Games
A1: Away_Team | B1: Home_Team | C1: Spread | D1: Will_Cover | E1: Confidence | F1: Result | G1: Date | H1: Success Rate % | J1: 2025-2026 SZN
H2: {=_xlfn.IFS(E2 = 1,$L$3,E2>=0.99,$L$4, E2>=0.95,$L$5, E2>= 0.93, $L$6, E2>= 0.9,$L$7, E2>= 0.85,$L$8, E2>= 0.8,$L$9, E2>= 0.75,$L$10, E2 >= 0.7, $L$11, E2>= 0.65, $L$12, E2>= 0.6, $L$13, E2>= 0.55,$L$14, E2 >= 0.5,$L$15)} -> #N/A | J2: CI LEVEL | K2: RECORD | L2: SUCCESS RATE | M2: LAST 10 DAYS | N2: UNITS | O2: RETURN
H3: {=_xlfn.IFS(E3 = 1,$L$3,E3>=0.99,$L$4, E3>=0.95,$L$5, E3>= 0.93, $L$6, E3>= 0.9,$L$7, E3>= 0.85,$L$8, E3>= 0.8,$L$9, E3>= 0.75,$L$10, E3 >= 0.7, $L$11, E3>= 0.65, $L$12, E3>= 0.6, $L$13, E3>= 0.55,$L$14, E3 >= 0.5,$L$15)} -> #N/A | J3: 1 | K3: 37-29 | L3: 0.56060606 | M3: 9-2 | N3: 5 | O3: 25.5
H4: {=_xlfn.IFS(E4 = 1,$L$3,E4>=0.99,$L$4, E4>=0.95,$L$5, E4>= 0.93, $L$6, E4>= 0.9,$L$7, E4>= 0.85,$L$8, E4>= 0.8,$L$9, E4>= 0.75,$L$10, E4 >= 0.7, $L$11, E4>= 0.65, $L$12, E4>= 0.6, $L$13, E4>= 0.55,$L$14, E4 >= 0.5,$L$15)} -> #N/A | J4: 99-99.9% | K4: 60-66 | L4: 0.47619048 | M4: 20-13 | N4: 1 | O4: -12.6
H5: {=_xlfn.IFS(E5 = 1,$L$3,E5>=0.99,$L$4, E5>=0.95,$L$5, E5>= 0.93, $L$6, E5>= 0.9,$L$7, E5>= 0.85,$L$8, E5>= 0.8,$L$9, E5>= 0.75,$L$10, E5 >= 0.7, $L$11, E5>= 0.65, $L$12, E5>= 0.6, $L$13, E5>= 0.55,$L$14, E5 >= 0.5,$L$15)} -> #N/A | J5: 95-99% | K5: 45-46 | L5: 0.49450549 | M5: 15-11 | N5: 0.5 | O5: -2.8
H6: {=_xlfn.IFS(E6 = 1,$L$3,E6>=0.99,$L$4, E6>=0.95,$L$5, E6>= 0.93, $L$6, E6>= 0.9,$L$7, E6>= 0.85,$L$8, E6>= 0.8,$L$9, E6>= 0.75,$L$10, E6 >= 0.7, $L$11, E6>= 0.65, $L$12, E6>= 0.6, $L$13, E6>= 0.55,$L$14, E6 >= 0.5,$L$15)} -> #N/A | J6: 93-95% | K6: 5-12 | L6: 0.29411765 | M6: 1-3 | N6: 1 | O6: -8.2
H7: {=_xlfn.IFS(E7 = 1,$L$3,E7>=0.99,$L$4, E7>=0.95,$L$5, E7>= 0.93, $L$6, E7>= 0.9,$L$7, E7>= 0.85,$L$8, E7>= 0.8,$L$9, E7>= 0.75,$L$10, E7 >= 0.7, $L$11, E7>= 0.65, $L$12, E7>= 0.6, $L$13, E7>= 0.55,$L$14, E7 >= 0.5,$L$15)} -> #N/A | J7: 90-93% | K7: 14-13 | L7: 0.51851852 | M7: 5-6 | N7: 2.5 | O7: -0.75
H8: {=_xlfn.IFS(E8 = 1,$L$3,E8>=0.99,$L$4, E8>=0.95,$L$5, E8>= 0.93, $L$6, E8>= 0.9,$L$7, E8>= 0.85,$L$8, E8>= 0.8,$L$9, E8>= 0.75,$L$10, E8 >= 0.7, $L$11, E8>= 0.65, $L$12, E8>= 0.6, $L$13, E8>= 0.55,$L$14, E8 >= 0.5,$L$15)} -> #N/A | J8: 85-90% | K8: 19-11 | L8: 0.63333333 | M8: 6-3 | N8: 2.5 | O8: 44.75
H9: {=_xlfn.IFS(E9 = 1,$L$3,E9>=0.99,$L$4, E9>=0.95,$L$5, E9>= 0.93, $L$6, E9>= 0.9,$L$7, E9>= 0.85,$L$8, E9>= 0.8,$L$9, E9>= 0.75,$L$10, E9 >= 0.7, $L$11, E9>= 0.65, $L$12, E9>= 0.6, $L$13, E9>= 0.55,$L$14, E9 >= 0.5,$L$15)} -> #N/A | J9: 80-85% | K9: 12-11 | L9: 0.52173913 | M9: 6-4 | N9: 1 | O9: 10.9
H10: {=_xlfn.IFS(E10 = 1,$L$3,E10>=0.99,$L$4, E10>=0.95,$L$5, E10>= 0.93, $L$6, E10>= 0.9,$L$7, E10>= 0.85,$L$8, E10>= 0.8,$L$9, E10>= 0.75,$L$10, E10 >= 0.7, $L$11, E10>= 0.65, $L$12, E10>= 0.6, $L$13, E10>= 0.55,$L$14, E10 >= 0.5,$L$15)} -> #N/A | J10: 75-80% | K10: 8-11 | L10: 0.42105263 | M10: 0-3 | N10: 1 | O10: -4.1
H11: {=_xlfn.IFS(E11 = 1,$L$3,E11>=0.99,$L$4, E11>=0.95,$L$5, E11>= 0.93, $L$6, E11>= 0.9,$L$7, E11>= 0.85,$L$8, E11>= 0.8,$L$9, E11>= 0.75,$L$10, E11 >= 0.7, $L$11, E11>= 0.65, $L$12, E11>= 0.6, $L$13, E11>= 0.55,$L$14, E11 >= 0.5,$L$15)} -> #N/A | J11: 70-75% | K11: 10-5 | L11: 0.66666667 | M11: 4-1 | N11: 1 | O11: 4.5
H12: {=_xlfn.IFS(E12 = 1,$L$3,E12>=0.99,$L$4, E12>=0.95,$L$5, E12>= 0.93, $L$6, E12>= 0.9,$L$7, E12>= 0.85,$L$8, E12>= 0.8,$L$9, E12>= 0.75,$L$10, E12 >= 0.7, $L$11, E12>= 0.65, $L$12, E12>= 0.6, $L$13, E12>= 0.55,$L$14, E12 >= 0.5,$L$15)} -> #N/A | J12: 65-70% | K12: 9-13 | L12: 0.40909091 | M12: 3-4 | N12: 2.5 | O12: 7.75
H13: {=_xlfn.IFS(E13 = 1,$L$3,E13>=0.99,$L$4, E13>=0.95,$L$5, E13>= 0.93, $L$6, E13>= 0.9,$L$7, E13>= 0.85,$L$8, E13>= 0.8,$L$9, E13>= 0.75,$L$10, E13 >= 0.7, $L$11, E13>= 0.65, $L$12, E13>= 0.6, $L$13, E13>= 0.55,$L$14, E13 >= 0.5,$L$15)} -> #N/A | J13: 60-65% | K13: 11-4 | L13: 0.73333333 | M13: 2-0 | N13: 0.5 | O13: 3.3
H14: {=_xlfn.IFS(E14 = 1,$L$3,E14>=0.99,$L$4, E14>=0.95,$L$5, E14>= 0.93, $L$6, E14>= 0.9,$L$7, E14>= 0.85,$L$8, E14>= 0.8,$L$9, E14>= 0.75,$L$10, E14 >= 0.7, $L$11, E14>= 0.65, $L$12, E14>= 0.6, $L$13, E14>= 0.55,$L$14, E14 >= 0.5,$L$15)} -> #N/A | J14: 55-60% | K14: 7-9 | L14: 0.4375 | M14: 1-2 | N14: 2 | O14: -5.8
H15: {=_xlfn.IFS(E15 = 1,$L$3,E15>=0.99,$L$4, E15>=0.95,$L$5, E15>= 0.93, $L$6, E15>= 0.9,$L$7, E15>= 0.85,$L$8, E15>= 0.8,$L$9, E15>= 0.75,$L$10, E15 >= 0.7, $L$11, E15>= 0.65, $L$12, E15>= 0.6, $L$13, E15>= 0.55,$L$14, E15 >= 0.5,$L$15)} -> #N/A | J15: 50-55% | K15: 5-8 | L15: 0.38461538 | M15: 1-3 | N15: 0.5 | O15: -1.9
H16: {=_xlfn.IFS(E16 = 1,$L$3,E16>=0.99,$L$4, E16>=0.95,$L$5, E16>= 0.93, $L$6, E16>= 0.9,$L$7, E16>= 0.85,$L$8, E16>= 0.8,$L$9, E16>= 0.75,$L$10, E16 >= 0.7, $L$11, E16>= 0.65, $L$12, E16>= 0.6, $L$13, E16>= 0.55,$L$14, E16 >= 0.5,$L$15)} -> #N/A
H17: {=_xlfn.IFS(E17 = 1,$L$3,E17>=0.99,$L$4, E17>=0.95,$L$5, E17>= 0.93, $L$6, E17>= 0.9,$L$7, E17>= 0.85,$L$8, E17>= 0.8,$L$9, E17>= 0.75,$L$10, E17 >= 0.7, $L$11, E17>= 0.65, $L$12, E17>= 0.6, $L$13, E17>= 0.55,$L$14, E17 >= 0.5,$L$15)} -> #N/A | J17: TOTAL | K17: 242-238 | N17: TOTAL | O17: 60.55
H18: {=_xlfn.IFS(E18 = 1,$L$3,E18>=0.99,$L$4, E18>=0.95,$L$5, E18>= 0.93, $L$6, E18>= 0.9,$L$7, E18>= 0.85,$L$8, E18>= 0.8,$L$9, E18>= 0.75,$L$10, E18 >= 0.7, $L$11, E18>= 0.65, $L$12, E18>= 0.6, $L$13, E18>= 0.55,$L$14, E18 >= 0.5,$L$15)} -> #N/A | K18: 0.50416667
H19: {=_xlfn.IFS(E19 = 1,$L$3,E19>=0.99,$L$4, E19>=0.95,$L$5, E19>= 0.93, $L$6, E19>= 0.9,$L$7, E19>= 0.85,$L$8, E19>= 0.8,$L$9, E19>= 0.75,$L$10, E19 >= 0.7, $L$11, E19>= 0.65, $L$12, E19>= 0.6, $L$13, E19>= 0.55,$L$14, E19 >= 0.5,$L$15)} -> #N/A
H20: {=_xlfn.IFS(E20 = 1,$L$3,E20>=0.99,$L$4, E20>=0.95,$L$5, E20>= 0.93, $L$6, E20>= 0.9,$L$7, E20>= 0.85,$L$8, E20>= 0.8,$L$9, E20>= 0.75,$L$10, E20 >= 0.7, $L$11, E20>= 0.65, $L$12, E20>= 0.6, $L$13, E20>= 0.55,$L$14, E20 >= 0.5,$L$15)} -> #N/A
H21: {=_xlfn.IFS(E21 = 1,$L$3,E21>=0.99,$L$4, E21>=0.95,$L$5, E21>= 0.93, $L$6, E21>= 0.9,$L$7, E21>= 0.85,$L$8, E21>= 0.8,$L$9, E21>= 0.75,$L$10, E21 >= 0.7, $L$11, E21>= 0.65, $L$12, E21>= 0.6, $L$13, E21>= 0.55,$L$14, E21 >= 0.5,$L$15)} -> #N/A
H22: {=_xlfn.IFS(E22 = 1,$L$3,E22>=0.99,$L$4, E22>=0.95,$L$5, E22>= 0.93, $L$6, E22>= 0.9,$L$7, E22>= 0.85,$L$8, E22>= 0.8,$L$9, E22>= 0.75,$L$10, E22 >= 0.7, $L$11, E22>= 0.65, $L$12, E22>= 0.6, $L$13, E22>= 0.55,$L$14, E22 >= 0.5,$L$15)} -> #N/A
H23: {=_xlfn.IFS(E23 = 1,$L$3,E23>=0.99,$L$4, E23>=0.95,$L$5, E23>= 0.93, $L$6, E23>= 0.9,$L$7, E23>= 0.85,$L$8, E23>= 0.8,$L$9, E23>= 0.75,$L$10, E23 >= 0.7, $L$11, E23>= 0.65, $L$12, E23>= 0.6, $L$13, E23>= 0.55,$L$14, E23 >= 0.5,$L$15)} -> #N/A
H24: {=_xlfn.IFS(E24 = 1,$L$3,E24>=0.99,$L$4, E24>=0.95,$L$5, E24>= 0.93, $L$6, E24>= 0.9,$L$7, E24>= 0.85,$L$8, E24>= 0.8,$L$9, E24>= 0.75,$L$10, E24 >= 0.7, $L$11, E24>= 0.65, $L$12, E24>= 0.6, $L$13, E24>= 0.55,$L$14, E24 >= 0.5,$L$15)} -> #N/A
H25: {=_xlfn.IFS(E25 = 1,$L$3,E25>=0.99,$L$4, E25>=0.95,$L$5, E25>= 0.93, $L$6, E25>= 0.9,$L$7, E25>= 0.85,$L$8, E25>= 0.8,$L$9, E25>= 0.75,$L$10, E25 >= 0.7, $L$11, E25>= 0.65, $L$12, E25>= 0.6, $L$13, E25>= 0.55,$L$14, E25 >= 0.5,$L$15)} -> #N/A
H26: {=_xlfn.IFS(E26 = 1,$L$3,E26>=0.99,$L$4, E26>=0.95,$L$5, E26>= 0.93, $L$6, E26>= 0.9,$L$7, E26>= 0.85,$L$8, E26>= 0.8,$L$9, E26>= 0.75,$L$10, E26 >= 0.7, $L$11, E26>= 0.65, $L$12, E26>= 0.6, $L$13, E26>= 0.55,$L$14, E26 >= 0.5,$L$15)} -> #N/A
H27: {=_xlfn.IFS(E27 = 1,$L$3,E27>=0.99,$L$4, E27>=0.95,$L$5, E27>= 0.93, $L$6, E27>= 0.9,$L$7, E27>= 0.85,$L$8, E27>= 0.8,$L$9, E27>= 0.75,$L$10, E27 >= 0.7, $L$11, E27>= 0.65, $L$12, E27>= 0.6, $L$13, E27>= 0.55,$L$14, E27 >= 0.5,$L$15)} -> #N/A
H28: {=_xlfn.IFS(E28 = 1,$L$3,E28>=0.99,$L$4, E28>=0.95,$L$5, E28>= 0.93, $L$6, E28>= 0.9,$L$7, E28>= 0.85,$L$8, E28>= 0.8,$L$9, E28>= 0.75,$L$10, E28 >= 0.7, $L$11, E28>= 0.65, $L$12, E28>= 0.6, $L$13, E28>= 0.55,$L$14, E28 >= 0.5,$L$15)} -> #N/A
H29: {=_xlfn.IFS(E29 = 1,$L$3,E29>=0.99,$L$4, E29>=0.95,$L$5, E29>= 0.93, $L$6, E29>= 0.9,$L$7, E29>= 0.85,$L$8, E29>= 0.8,$L$9, E29>= 0.75,$L$10, E29 >= 0.7, $L$11, E29>= 0.65, $L$12, E29>= 0.6, $L$13, E29>= 0.55,$L$14, E29 >= 0.5,$L$15)} -> #N/A
H30: {=_xlfn.IFS(E30 = 1,$L$3,E30>=0.99,$L$4, E30>=0.95,$L$5, E30>= 0.93, $L$6, E30>= 0.9,$L$7, E30>= 0.85,$L$8, E30>= 0.8,$L$9, E30>= 0.75,$L$10, E30 >= 0.7, $L$11, E30>= 0.65, $L$12, E30>= 0.6, $L$13, E30>= 0.55,$L$14, E30 >= 0.5,$L$15)} -> #N/A
... H48: {=_xlfn.IFS(E48 = 1,$L$3,E48>=0.99,$L$4, E48>=0.95,$L$5, E48>= 0.93, $L$6, E48>= 0.9,$L$7, E48>= 0.85,$L$8, E48>= 0.8,$L$9, E48>= 0.75,$L$10, E48 >= 0.7, $L$11, E48>= 0.65, $L$12, E48>= 0.6, $L$13, E48>= 0.55,$L$14, E48 >= 0.5,$L$15)} -> #N/A

Sheet 2025-2026 Record
A1: Away_Team | B1: Home_Team | C1: Spread | D1: Will_Cover | E1: Confidence | F1: Result | G1: Date | H1: Success Rate | J1: 2025-2026 SZN | Q1: 2025 (Feb-March) SZN
A2: Jacksonville | B2: Texas A&M | C2: -26.5 | D2: TRUE | E2: 0.9975 | F2: Y | G2: 46005 | H2: {=_xlfn.IFS(E2 = 1,$L$3,E2>=0.99,$L$4, E2>=0.95,$L$5, E2>= 0.93, $L$6, E2>= 0.9,$L$7, E2>= 0.85,$L$8, E2>= 0.8,$L$9, E2>= 0.75,$L$10, E2 >= 0.7, $L$11, E2>= 0.65, $L$12, E2>= 0.6, $L$13, E2>= 0.55,$L$14, E2 >= 0.5,$L$15)} -> 0.484375 | J2: CI LEVEL | K2: RECORD | L2: SUCCESS RATE | M2: LAST 10 DAYS | N2: UNITS | O2: RETURN | Q2: CI LEVEL | R2: RECORD | S2: SUCCESS RATE | T2: UNITS | U2: RETURN
A3: Queens | B3: Wake Forest | C3: -18.5 | D3: TRUE | E3: 0.99 | F3: Y | G3: 46005 | H3: {=_xlfn.IFS(E3 = 1,$L$3,E3>=0.99,$L$4, E3>=0.95,$L$5, E3>= 0.93, $L$6, E3>= 0.9,$L$7, E3>= 0.85,$L$8, E3>= 0.8,$L$9, E3>= 0.75,$L$10, E3 >= 0.7, $L$11, E3>= 0.65, $L$12, E3>= 0.6, $L$13, E3>= 0.55,$L$14, E3 >= 0.5,$L$15)} -> 0.484375 | J3: 1 | K3: =COUNTIFS(E:E,1,F:F,"Y") & "-" & COUNTIFS(E:E,1,F:F,"N") -> 37-29 | L3: =IFERROR(LEFT(K3,2)/SUM(LEFT(K3,2),RIGHT(K3,2)), "NA") -> 0.56060606 | M3: =COUNTIFS(G:G,">="&TODAY()-10,E:E,"=1",F:F,"Y")& "-" & COUNTIFS(G:G,">="&TODAY()-10,E:E,"=1",F:F,"N") -> 9-2 | N3: 5 | O3: =N3*(LEFT(K3,2)-(1.1*RIGHT(K3,2))) -> 25.5 | Q3: 1 | R3: 8-2 | S3: 0.8 | T3: 5 | U3: 29
A4: Washington State | B4: USC | C4: -14.5 | D4: TRUE | E4: 0.985 | F4: N | G4: 46005 | H4: {=_xlfn.IFS(E4 = 1,$L$3,E4>=0.99,$L$4, E4>=0.95,$L$5, E4>= 0.93, $L$6, E4>= 0.9,$L$7, E4>= 0.85,$L$8, E4>= 0.8,$L$9, E4>= 0.75,$L$10, E4 >= 0.7, $L$11, E4>= 0.65, $L$12, E4>= 0.6, $L$13, E4>= 0.55,$L$14, E4 >= 0.5,$L$15)} -> 0.48387097 | J4: 99-99.9% | K4: =COUNTIFS(E:E,">=.99",E:E,"<1",F:F,"Y") & "-" & COUNTIFS(E:E,">=.99",E:E,"<1",F:F,"N") -> 62-66 | L4: =IFERROR(LEFT(K4,2)/SUM(LEFT(K4,2),RIGHT(K4,2)), "NA") -> 0.484375 | M4: =COUNTIFS(G:G,">="&TODAY()-10,E:E,">=0.99",E:E,"<1",F:F,"Y") & "-" & COUNTIFS(G:G,">="&TODAY()-10,E:E,">=0.99",E:E,"<1",F:F,"N") -> 22-13 | N4: 1 | O4: =N4*(LEFT(K4,2)-(1.1*RIGHT(K4,2))) -> -10.6 | Q4: 99-99.9% | R4: 17-13 | S4: 0.56666667 | T4: 2 | U4: 5.4
A5: Troy | B5: UAB | C5: -7.5 | D5: TRUE | E5: 0.9625 | F5: N | G5: 46005 | H5: {=_xlfn.IFS(E5 = 1,$L$3,E5>=0.99,$L$4, E5>=0.95,$L$5, E5>= 0.93, $L$6, E5>= 0.9,$L$7, E5>= 0.85,$L$8, E5>= 0.8,$L$9, E5>= 0.75,$L$10, E5 >= 0.7, $L$11, E5>= 0.65, $L$12, E5>= 0.6, $L$13, E5>= 0.55,$L$14, E5 >= 0.5,$L$15)} -> 0.48387097 | J5: 95-99% | K5: =COUNTIFS(E:E,">=.95",E:E,"<0.99",F:F,"Y") & "-" & COUNTIFS(E:E,">=.95",E:E,"<0.99",F:F,"N") -> 45-48 | L5: =IFERROR(LEFT(K5,2)/SUM(LEFT(K5,2),RIGHT(K5,2)), "NA") -> 0.48387097 | M5: =COUNTIFS(G:G,">="&TODAY()-10,E:E,">=0.95",E:E,"<.99",F:F,"Y") & "-" & COUNTIFS(G:G,">="&TODAY()-10,E:E,">=0.95",E:E,"<.99",F:F,"N") -> 15-12 | N5: 0.5 | O5: =N5*(LEFT(K5,2)-(1.1*RIGHT(K5,2))) -> -3.9 | Q5: 95-99% | R5: 21-21 | S5: 0.5 | T5: 0.5 | U5: -1.05
A6: Merrimack | B6: Vermont | C6: -6.5 | D6: TRUE | E6: 0.92 | F6: Y | G6: 46005 | H6: {=_xlfn.IFS(E6 = 1,$L$3,E6>=0.99,$L$4, E6>=0.95,$L$5, E6>= 0.93, $L$6, E6>= 0.9,$L$7, E6>= 0.85,$L$8, E6>= 0.8,$L$9, E6>= 0.75,$L$10, E6 >= 0.7, $L$11, E6>= 0.65, $L$12, E6>= 0.6, $L$13, E6>= 0.55,$L$14, E6 >= 0.5,$L$15)} -> 0.55172414 | J6: 93-95% | K6: =COUNTIFS(E:E,">=.93",E:E,"<0.95",F:F,"Y") & "-" & COUNTIFS(E:E,">=.93",E:E,"<0.95",F:F,"N") -> 5-12 | L6: =IFERROR(LEFT(K6)/SUM(LEFT(K6),RIGHT(K6,2)), "NA") -> 0.29411765 | M6: =COUNTIFS(G:G,">="&TODAY()-10,E:E,">=0.93",E:E,"<0.95",F:F,"Y") & "-" & COUNTIFS(G:G,">="&TODAY()-10,E:E,">=0.93",E:E,"<0.95",F:F,"N") -> 1-2 | N6: 1 | O6: =N6*(LEFT(K6,1)-(1.1*RIGHT(K6,2))) -> -8.2 | Q6: 93-95% | R6: 9-12 | S6: 0.42857143 | T6: 1.5 | U6: -6.3
A7: Coppin State | B7: Radford | C7: -19.5 | D7: TRUE | E7: 0.9025 | F7: Y | G7: 46005 | H7: {=_xlfn.IFS(E7 = 1,$L$3,E7>=0.99,$L$4, E7>=0.95,$L$5, E7>= 0.93, $L$6, E7>= 0.9,$L$7, E7>= 0.85,$L$8, E7>= 0.8,$L$9, E7>= 0.75,$L$10, E7 >= 0.7, $L$11, E7>= 0.65, $L$12, E7>= 0.6, $L$13, E7>= 0.55,$L$14, E7 >= 0.5,$L$15)} -> 0.55172414 | J7: 90-93% | K7: =COUNTIFS(E:E,">=.90",E:E,"<0.93",F:F,"Y") & "-" & COUNTIFS(E:E,">=.90",E:E,"<0.93",F:F,"N") -> 16-13 | L7: =IFERROR(LEFT(K7,2)/SUM(LEFT(K7,2),RIGHT(K7,2)), "NA") -> 0.55172414 | M7: =COUNTIFS(G:G,">="&TODAY()-10,E:E,">=0.9",E:E,"<.93",F:F,"Y") & "-" & COUNTIFS(G:G,">="&TODAY()-10,E:E,">=0.9",E:E,"<.93",F:F,"N") -> 7-6 | N7: 2.5 | O7: =N7*(LEFT(K7,2)-(1.1*RIGHT(K7,2))) -> 4.25 | Q7: 90-93% | R7: 11-5 | S7: 0.6875 | T7: 3 | U7: -13.5
A8: Ball State | B8: Campbell | C8: -7.5 | D8: TRUE | E8: 0.885 | F8: N | G8: 46005 | H8: {=_xlfn.IFS(E8 = 1,$L$3,E8>=0.99,$L$4, E8>=0.95,$L$5, E8>= 0.93, $L$6, E8>= 0.9,$L$7, E8>= 0.85,$L$8, E8>= 0.8,$L$9, E8>= 0.75,$L$10, E8 >= 0.7, $L$11, E8>= 0.65, $L$12, E8>= 0.6, $L$13, E8>= 0.55,$L$14, E8 >= 0.5,$L$15)} -> 0.61290323 | J8: 85-90% | K8: =COUNTIFS(E:E,">=.85",E:E,"<0.90",F:F,"Y") & "-" & COUNTIFS(E:E,">=.85",E:E,"<0.90",F:F,"N") -> 19-12 | L8: =IFERROR(LEFT(K8,2)/SUM(LEFT(K8,2),RIGHT(K8,2)), "NA") -> 0.61290323 | M8: =COUNTIFS(G:G,">="&TODAY()-10,E:E,">=0.85",E:E,"<0.90",F:F,"Y")& "-" & COUNTIFS(G:G,">="&TODAY()-10,E:E,">=0.85",E:E,"<0.90",F:F,"N") -> 6-4 | N8: 2.5 | O8: =N8*(LEFT(K8,2)-(1.1*RIGHT(K8,1))) -> 42 | Q8: 85-90% | R8: 12-28 | S8: 0.3 | T8: 3 | U8: 56.4 | V8: fade
A9: Charlotte | B9: Charleston | C9: -5.5 | D9: TRUE | E9: 0.8375 | F9: Y | G9: 46005 | H9: {=_xlfn.IFS(E9 = 1,$L$3,E9>=0.99,$L$4, E9>=0.95,$L$5, E9>= 0.93, $L$6, E9>= 0.9,$L$7, E9>= 0.85,$L$8, E9>= 0.8,$L$9, E9>= 0.75,$L$10, E9 >= 0.7, $L$11, E9>= 0.65, $L$12, E9>= 0.6, $L$13, E9>= 0.55,$L$14, E9 >= 0.5,$L$15)} -> 0.54166667 | J9: 80-85% | K9: =COUNTIFS(E:E,">=.80",E:E,"<0.85",F:F,"Y") & "-" & COUNTIFS(E:E,">=.80",E:E,"<0.85",F:F,"N") -> 13-11 | L9: =IFERROR(LEFT(K9,2)/SUM(LEFT(K9,2),RIGHT(K9,2)), "NA") -> 0.54166667 | M9: =COUNTIFS(G:G,">="&TODAY()-10,E:E,">=0.80",E:E,"<0.85",F:F,"Y")& "-" & COUNTIFS(G:G,">="&TODAY()-10,E:E,">=0.80",E:E,"<0.85",F:F,"N") -> 7-4 | N9: 1 | O9: =N9*(LEFT(K9,2)-(1.1*RIGHT(K9,1))) -> 11.9 | Q9: 80-85% | R9: 17-19 | S9: 0.47222222 | T9: 0.5 | U9: -1.95
A10: Indiana State | B10: Milwaukee | C10: -4.5 | D10: TRUE | E10: 0.64 | F10: N | G10: 46005 | H10: {=_xlfn.IFS(E10 = 1,$L$3,E10>=0.99,$L$4, E10>=0.95,$L$5, E10>= 0.93, $L$6, E10>= 0.9,$L$7, E10>= 0.85,$L$8, E10>= 0.8,$L$9, E10>= 0.75,$L$10, E10 >= 0.7, $L$11, E10>= 0.65, $L$12, E10>= 0.6, $L$13, E10>= 0.55,$L$14, E10 >= 0.5,$L$15)} -> 0.6875 | J10: 75-80% | K10: =COUNTIFS(E:E,">=.75",E:E,"<0.80",F:F,"Y") & "-" & COUNTIFS(E:E,">=.75",E:E,"<0.80",F:F,"N") -> 8-11 | L10: =IFERROR(LEFT(K10)/SUM(LEFT(K10),RIGHT(K10,2)), "NA") -> 0.42105263 | M10: =COUNTIFS(G:G,">="&TODAY()-10,E:E,">=0.75",E:E,"<0.80",F:F,"Y")& "-" & COUNTIFS(G:G,">="&TODAY()-10,E:E,">=0.75",E:E,"<0.80",F:F,"N") -> 0-3 | N10: 1 | O10: =N10*(LEFT(K10,1)-(1.1*RIGHT(K10,2))) -> -4.1 | Q10: 75-80% | R10: 8-5 | S10: 0.61538462 | T10: 1.5 | U10: 3.75
A11: UC Riverside | B11: BYU | C11: -35 | D11: TRUE | E11: 1 | F11: Y | G11: 46004 | H11: {=_xlfn.IFS(E11 = 1,$L$3,E11>=0.99,$L$4, E11>=0.95,$L$5, E11>= 0.93, $L$6, E11>= 0.9,$L$7, E11>= 0.85,$L$8, E11>= 0.8,$L$9, E11>= 0.75,$L$10, E11 >= 0.7, $L$11, E11>= 0.65, $L$12, E11>= 0.6, $L$13, E11>= 0.55,$L$14, E11 >= 0.5,$L$15)} -> 0.56060606 | J11: 70-75% | K11: =COUNTIFS(E:E,">=.70",E:E,"<0.75",F:F,"Y") & "-" & COUNTIFS(E:E,">=.70",E:E,"<0.75",F:F,"N") -> 10-5 | L11: =IFERROR(LEFT(K11,2)/SUM(LEFT(K11,2),RIGHT(K11)), "NA") -> 0.66666667 | M11: =COUNTIFS(G:G,">="&TODAY()-10,E:E,">=0.70",E:E,"<0.75",F:F,"Y")& "-" & COUNTIFS(G:G,">="&TODAY()-10,E:E,">=0.70",E:E,"<0.75",F:F,"N") -> 4-1 | N11: 1 | O11: =N11*(LEFT(K11,2)-(1.1*RIGHT(K11,1))) -> 4.5 | Q11: 70-75% | R11: 9-11 | S11: 0.45 | T11: 1 | U11: 7.9
A12: Mercyhurst | B12: Davidson | C12: -13.5 | D12: TRUE | E12: 1 | F12: Y | G12: 46004 | H12: {=_xlfn.IFS(E12 = 1,$L$3,E12>=0.99,$L$4, E12>=0.95,$L$5, E12>= 0.93, $L$6, E12>= 0.9,$L$7, E12>= 0.85,$L$8, E12>= 0.8,$L$9, E12>= 0.75,$L$10, E12 >= 0.7, $L$11, E12>= 0.65, $L$12, E12>= 0.6, $L$13, E12>= 0.55,$L$14, E12 >= 0.5,$L$15)} -> 0.56060606 | J12: 65-70% | K12: =COUNTIFS(E:E,">=.65",E:E,"<0.70",F:F,"Y") & "-" & COUNTIFS(E:E,">=.65",E:E,"<0.70",F:F,"N") -> 9-13 | L12: =IFERROR(LEFT(K12)/SUM(LEFT(K12),RIGHT(K12,2)), "NA") -> 0.40909091 | M12: =COUNTIFS(G:G,">="&TODAY()-10,E:E,">=0.65",E:E,"<0.70",F:F,"Y")& "-" & COUNTIFS(G:G,">="&TODAY()-10,E:E,">=0.65",E:E,"<0.70",F:F,"N") -> 3-4 | N12: 2.5 | O12: =N12*(RIGHT(K12,2)-(1.1*LEFT(K12,1))) -> 7.75 | Q12: 65-70% | R12: 16-6 | S12: 0.72727273 | T12: 3 | U12: 28.2
A13: Albany (NY) | B13: Florida Atlantic | C13: -16.5 | D13: TRUE | E13: 1 | F13: Y | G13: 46004 | H13: {=_xlfn.IFS(E13 = 1,$L$3,E13>=0.99,$L$4, E13>=0.95,$L$5, E13>= 0.93, $L$6, E13>= 0.9,$L$7, E13>= 0.85,$L$8, E13>= 0.8,$L$9, E13>= 0.75,$L$10, E13 >= 0.7, $L$11, E13>= 0.65, $L$12, E13>= 0.6, $L$13, E13>= 0.55,$L$14, E13 >= 0.5,$L$15)} -> 0.56060606 | J13: 60-65% | K13: =COUNTIFS(E:E,">=.60",E:E,"<0.65",F:F,"Y") & "-" & COUNTIFS(E:E,">=.60",E:E,"<0.65",F:F,"N") -> 11-5 | L13: =IFERROR(LEFT(K13,2)/SUM(LEFT(K13,2),RIGHT(K13)), "NA") -> 0.6875 | M13: =COUNTIFS(G:G,">="&TODAY()-10,E:E,">=0.60",E:E,"<0.65",F:F,"Y")& "-" & COUNTIFS(G:G,">="&TODAY()-10,E:E,">=0.60",E:E,"<0.65",F:F,"N") -> 2-1 | N13: 0.5 | O13: =N13*(LEFT(K13,2)-(1.1*RIGHT(K13,1))) -> 2.75 | Q13: 60-65% | R13: 10-11 | S13: 0.47619048 | T13: 0.5 | U13: -1.05
A14: UC Davis | B14: Oregon | C14: -13.5 | D14: TRUE | E14: 1 | F14: Y | G14: 46004 | H14: {=_xlfn.IFS(E14 = 1,$L$3,E14>=0.99,$L$4, E14>=0.95,$L$5, E14>= 0.93, $L$6, E14>= 0.9,$L$7, E14>= 0.85,$L$8, E14>= 0.8,$L$9, E14>= 0.75,$L$10, E14 >= 0.7, $L$11, E14>= 0.65, $L$12, E14>= 0.6, $L$13, E14>= 0.55,$L$14, E14 >= 0.5,$L$15)} -> 0.56060606 | J14: 55-60% | K14: =COUNTIFS(E:E,">=.55",E:E,"<0.60",F:F,"Y") & "-" & COUNTIFS(E:E,">=.55",E:E,"<0.60",F:F,"N") -> 7-9 | L14: =IFERROR(LEFT(K14)/SUM(LEFT(K14),RIGHT(K14)), "NA") -> 0.4375 | M14: =COUNTIFS(G:G,">="&TODAY()-10,E:E,">=0.55",E:E,"<0.60",F:F,"Y")& "-" & COUNTIFS(G:G,">="&TODAY()-10,E:E,">=0.55",E:E,"<0.60",F:F,"N") -> 1-2 | N14: 2 | O14: =N14*(LEFT(K14,1)-(1.1*RIGHT(K14,1))) -> -5.8 | Q14: 55-60% | R14: 15-5 | S14: 0.75 | T14: 2 | U14: 19
A15: Saint Peter's | B15: Georgetown | C15: -18.5 | D15: TRUE | E15: 0.9975 | F15: N | G15: 46004 | H15: {=_xlfn.IFS(E15 = 1,$L$3,E15>=0.99,$L$4, E15>=0.95,$L$5, E15>= 0.93, $L$6, E15>= 0.9,$L$7, E15>= 0.85,$L$8, E15>= 0.8,$L$9, E15>= 0.75,$L$10, E15 >= 0.7, $L$11, E15>= 0.65, $L$12, E15>= 0.6, $L$13, E15>= 0.55,$L$14, E15 >= 0.5,$L$15)} -> 0.484375 | J15: 50-55% | K15: =COUNTIFS(E:E,">=.50",E:E,"<0.55",F:F,"Y") & "-" & COUNTIFS(E:E,">=.50",E:E,"<0.55",F:F,"N") -> 5-8 | L15: =IFERROR(LEFT(K15)/SUM(LEFT(K15),RIGHT(K15)), "NA") -> 0.38461538 | M15: =COUNTIFS(G:G,">="&TODAY()-10,E:E,">=0.50",E:E,"<0.55",F:F,"Y")& "-" & COUNTIFS(G:G,">="&TODAY()-10,E:E,">=0.50",E:E,"<0.55",F:F,"N") -> 1-3 | N15: 0.5 | O15: =N15*(LEFT(K15,1)-(1.1*RIGHT(K15,1))) -> -1.9 | Q15: 50-55% | R15: 7-14 | S15: 0.33333333 | T15: 0.5 | U15: -4.2 | V15: ** could be a fade, tbd
A16: Mercer | B16: Clemson | C16: -22.5 | D16: TRUE | E16: 0.9975 | F16: N | G16: 46004 | H16: {=_xlfn.IFS(E16 = 1,$L$3,E16>=0.99,$L$4, E16>=0.95,$L$5, E16>= 0.93, $L$6, E16>= 0.9,$L$7, E16>= 0.85,$L$8, E16>= 0.8,$L$9, E16>= 0.75,$L$10, E16 >= 0.7, $L$11, E16>= 0.65, $L$12, E16>= 0.6, $L$13, E16>= 0.55,$L$14, E16 >= 0.5,$L$15)} -> 0.484375
A17: Old Dominion | B17: George Mason | C17: -16.5 | D17: TRUE | E17: 0.9975 | F17: N | G17: 46004 | H17: {=_xlfn.IFS(E17 = 1,$L$3,E17>=0.99,$L$4, E17>=0.95,$L$5, E17>= 0.93, $L$6, E17>= 0.9,$L$7, E17>= 0.85,$L$8, E17>= 0.8,$L$9, E17>= 0.75,$L$10, E17 >= 0.7, $L$11, E17>= 0.65, $L$12, E17>= 0.6, $L$13, E17>= 0.55,$L$14, E17 >= 0.5,$L$15)} -> 0.484375 | J17: TOTAL | K17: =COUNTIF(F:F,"Y") & "-" & COUNTIF(F:F,"N") -> 247-242 | N17: TOTAL | O17: =SUM(O3:O15) -> 64.15 | Q17: TOTAL | R17: =16+COUNTIF(Games!M:M,"Y") & "-" & COUNTIF(Games!M:M,"N")-16 -> 176-136 | T17: TOTAL | U17: =SUM(U3:U15) -> 121.6
A18: Rutgers | B18: Seton Hall | C18: -11.5 | D18: TRUE | E18: 0.9975 | F18: Y | G18: 46004 | H18: {=_xlfn.IFS(E18 = 1,$L$3,E18>=0.99,$L$4, E18>=0.95,$L$5, E18>= 0.93, $L$6, E18>= 0.9,$L$7, E18>= 0.85,$L$8, E18>= 0.8,$L$9, E18>= 0.75,$L$10, E18 >= 0.7, $L$11, E18>= 0.65, $L$12, E18>= 0.6, $L$13, E18>= 0.55,$L$14, E18 >= 0.5,$L$15)} -> 0.484375 | K18: =LEFT(K17,3)/SUM(LEFT(K17,3),RIGHT(K17,3)) -> 0.50511247
A19: Evansville | B19: Notre Dame | C19: -16.5 | D19: TRUE | E19: 0.9975 | F19: Y | G19: 46004 | H19: {=_xlfn.IFS(E19 = 1,$L$3,E19>=0.99,$L$4, E19>=0.95,$L$5, E19>= 0.93, $L$6, E19>= 0.9,$L$7, E19>= 0.85,$L$8, E19>= 0.8,$L$9, E19>= 0.75,$L$10, E19 >= 0.7, $L$11, E19>= 0.65, $L$12, E19>= 0.6, $L$13, E19>= 0.55,$L$14, E19 >= 0.5,$L$15)} -> 0.484375 | J19: ** the above is this years results tracked, to the right is a side by side comparison to last years Feb-March results
A20: Jackson State | B20: Northwestern | C20: -29.5 | D20: TRUE | E20: 0.9975 | F20: Y | G20: 46004 | H20: {=_xlfn.IFS(E20 = 1,$L$3,E20>=0.99,$L$4, E20>=0.95,$L$5, E20>= 0.93, $L$6, E20>= 0.9,$L$7, E20>= 0.85,$L$8, E20>= 0.8,$L$9, E20>= 0.75,$L$10, E20 >= 0.7, $L$11, E20>= 0.65, $L$12, E20>= 0.6, $L$13, E20>= 0.55,$L$14, E20 >= 0.5,$L$15)} -> 0.484375 | K20: ** the kenpom data gets more accurate to how good a team is the further along the season,
A21: UTSA | B21: Colorado | C21: -24 | D21: TRUE | E21: 0.9975 | F21: P | G21: 46004 | H21: {=_xlfn.IFS(E21 = 1,$L$3,E21>=0.99,$L$4, E21>=0.95,$L$5, E21>= 0.93, $L$6, E21>= 0.9,$L$7, E21>= 0.85,$L$8, E21>= 0.8,$L$9, E21>= 0.75,$L$10, E21 >= 0.7, $L$11, E21>= 0.65, $L$12, E21>= 0.6, $L$13, E21>= 0.55,$L$14, E21 >= 0.5,$L$15)} -> 0.484375 | J21: ***However, the 100% Confidence Interval is our best success and has spit out more games early in the szn because of matchups,
A22: Illinois Chicago | B22: Belmont | C22: -14.5 | D22: TRUE | E22: 0.995 | F22: N | G22: 46004 | H22: {=_xlfn.IFS(E22 = 1,$L$3,E22>=0.99,$L$4, E22>=0.95,$L$5, E22>= 0.93, $L$6, E22>= 0.9,$L$7, E22>= 0.85,$L$8, E22>= 0.8,$L$9, E22>= 0.75,$L$10, E22 >= 0.7, $L$11, E22>= 0.65, $L$12, E22>= 0.6, $L$13, E22>= 0.55,$L$14, E22 >= 0.5,$L$15)} -> 0.484375 | J22: opposed to last years had fewer towards the end of the szn
A23: UMass Lowell | B23: Quinnipiac | C23: -12.5 | D23: TRUE | E23: 0.995 | F23: N | G23: 46004 | H23: {=_xlfn.IFS(E23 = 1,$L$3,E23>=0.99,$L$4, E23>=0.95,$L$5, E23>= 0.93, $L$6, E23>= 0.9,$L$7, E23>= 0.85,$L$8, E23>= 0.8,$L$9, E23>= 0.75,$L$10, E23 >= 0.7, $L$11, E23>= 0.65, $L$12, E23>= 0.6, $L$13, E23>= 0.55,$L$14, E23 >= 0.5,$L$15)} -> 0.484375
A24: San Francisco | B24: Saint Louis | C24: -11.5 | D24: TRUE | E24: 0.995 | F24: N | G24: 46004 | H24: {=_xlfn.IFS(E24 = 1,$L$3,E24>=0.99,$L$4, E24>=0.95,$L$5, E24>= 0.93, $L$6, E24>= 0.9,$L$7, E24>= 0.85,$L$8, E24>= 0.8,$L$9, E24>= 0.75,$L$10, E24 >= 0.7, $L$11, E24>= 0.65, $L$12, E24>= 0.6, $L$13, E24>= 0.55,$L$14, E24 >= 0.5,$L$15)} -> 0.484375
A25: The Citadel | B25: South Carolina | C25: -23.5 | D25: TRUE | E25: 0.9925 | F25: Y | G25: 46004 | H25: {=_xlfn.IFS(E25 = 1,$L$3,E25>=0.99,$L$4, E25>=0.95,$L$5, E25>= 0.93, $L$6, E25>= 0.9,$L$7, E25>= 0.85,$L$8, E25>= 0.8,$L$9, E25>= 0.75,$L$10, E25 >= 0.7, $L$11, E25>= 0.65, $L$12, E25>= 0.6, $L$13, E25>= 0.55,$L$14, E25 >= 0.5,$L$15)} -> 0.484375
A26: Marquette | B26: Purdue | C26: -18.5 | D26: TRUE | E26: 0.9925 | F26: Y | G26: 46004 | H26: {=_xlfn.IFS(E26 = 1,$L$3,E26>=0.99,$L$4, E26>=0.95,$L$5, E26>= 0.93, $L$6, E26>= 0.9,$L$7, E26>= 0.85,$L$8, E26>= 0.8,$L$9, E26>= 0.75,$L$10, E26 >= 0.7, $L$11, E26>= 0.65, $L$12, E26>= 0.6, $L$13, E26>= 0.55,$L$14, E26 >= 0.5,$L$15)} -> 0.484375
A27: Louisiana | B27: Louisiana Tech | C27: -10.5 | D27: TRUE | E27: 0.9825 | F27: Y | G27: 46004 | H27: {=_xlfn.IFS(E27 = 1,$L$3,E27>=0.99,$L$4, E27>=0.95,$L$5, E27>= 0.93, $L$6, E27>= 0.9,$L$7, E27>= 0.85,$L$8, E27>= 0.8,$L$9, E27>= 0.75,$L$10, E27 >= 0.7, $L$11, E27>= 0.65, $L$12, E27>= 0.6, $L$13, E27>= 0.55,$L$14, E27 >= 0.5,$L$15)} -> 0.48387097
A28: New Orleans | B28: Houston | C28: -32.5 | D28: TRUE | E28: 0.9825 | F28: Y | G28: 46004 | H28: {=_xlfn.IFS(E28 = 1,$L$3,E28>=0.99,$L$4, E28>=0.95,$L$5, E28>= 0.93, $L$6, E28>= 0.9,$L$7, E28>= 0.85,$L$8, E28>= 0.8,$L$9, E28>= 0.75,$L$10, E28 >= 0.7, $L$11, E28>= 0.65, $L$12, E28>= 0.6, $L$13, E28>= 0.55,$L$14, E28 >= 0.5,$L$15)} -> 0.48387097
A29: Hofstra | B29: Syracuse | C29: -11.5 | D29: TRUE | E29: 0.98 | F29: N | G29: 46004 | H29: {=_xlfn.IFS(E29 = 1,$L$3,E29>=0.99,$L$4, E29>=0.95,$L$5, E29>= 0.93, $L$6, E29>= 0.9,$L$7, E29>= 0.85,$L$8, E29>= 0.8,$L$9, E29>= 0.75,$L$10, E29 >= 0.7, $L$11, E29>= 0.65, $L$12, E29>= 0.6, $L$13, E29>= 0.55,$L$14, E29 >= 0.5,$L$15)} -> 0.48387097
A30: Pitt | B30: Villanova | C30: -10.5 | D30: TRUE | E30: 0.975 | F30: Y | G30: 46004 | H30: {=_xlfn.IFS(E30 = 1,$L$3,E30>=0.99,$L$4, E30>=0.95,$L$5, E30>= 0.93, $L$6, E30>= 0.9,$L$7, E30>= 0.85,$L$8, E30>= 0.8,$L$9, E30>= 0.75,$L$10, E30 >= 0.7, $L$11, E30>= 0.65, $L$12, E30>= 0.6, $L$13, E30>= 0.55,$L$14, E30 >= 0.5,$L$15)} -> 0.48387097
A31: Nebraska | B31: Illinois | C31: -10.5 | D31: TRUE | E31: 0.9725 | F31: N | G31: 46004 | H31: {=_xlfn.IFS(E31 = 1,$L$3,E31>=0.99,$L$4, E31>=0.95,$L$5, E31>= 0.93, $L$6, E31>= 0.9,$L$7, E31>= 0.85,$L$8, E31>= 0.8,$L$9, E31>= 0.75,$L$10, E31 >= 0.7, $L$11, E31>= 0.65, $L$12, E31>= 0.6, $L$13, E31>= 0.55,$L$14, E31 >= 0.5,$L$15)} -> 0.48387097
A32: Memphis | B32: Louisville | C32: -15.5 | D32: TRUE | E32: 0.955 | F32: Y | G32: 46004 | H32: {=_xlfn.IFS(E32 = 1,$L$3,E32>=0.99,$L$4, E32>=0.95,$L$5, E32>= 0.93, $L$6, E32>= 0.9,$L$7, E32>= 0.85,$L$8, E32>= 0.8,$L$9, E32>= 0.75,$L$10, E32 >= 0.7, $L$11, E32>= 0.65, $L$12, E32>= 0.6, $L$13, E32>= 0.55,$L$14, E32 >= 0.5,$L$15)} -> 0.48387097
A33: Delaware State | B33: Longwood | C33: -14.5 | D33: TRUE | E33: 0.9525 | F33: N | G33: 46004 | H33: {=_xlfn.IFS(E33 = 1,$L$3,E33>=0.99,$L$4, E33>=0.95,$L$5, E33>= 0.93, $L$6, E33>= 0.9,$L$7, E33>= 0.85,$L$8, E33>= 0.8,$L$9, E33>= 0.75,$L$10, E33 >= 0.7, $L$11, E33>= 0.65, $L$12, E33>= 0.6, $L$13, E33>= 0.55,$L$14, E33 >= 0.5,$L$15)} -> 0.48387097
A34: DePaul | B34: Wichita State | C34: -6.5 | D34: TRUE | E34: 0.93 | F34: N | G34: 46004 | H34: {=_xlfn.IFS(E34 = 1,$L$3,E34>=0.99,$L$4, E34>=0.95,$L$5, E34>= 0.93, $L$6, E34>= 0.9,$L$7, E34>= 0.85,$L$8, E34>= 0.8,$L$9, E34>= 0.75,$L$10, E34 >= 0.7, $L$11, E34>= 0.65, $L$12, E34>= 0.6, $L$13, E34>= 0.55,$L$14, E34 >= 0.5,$L$15)} -> 0.29411765
... A265: VMI | B265: Richmond | C265: -12.5 | D265: TRUE | E265: 0.9975 | F265: Y | G265: 45980 | H265: {=_xlfn.IFS(E265 = 1,$L$3,E265>=0.99,$L$4, E265>=0.95,$L$5, E265>= 0.93, $L$6, E265>= 0.9,$L$7, E265>= 0.85,$L$8, E265>= 0.8,$L$9, E265>= 0.75,$L$10, E265 >= 0.7, $L$11, E265>= 0.65, $L$12, E265>= 0.6, $L$13, E265>= 0.55,$L$14, E265 >= 0.5,$L$15)} -> 0.484375
A266: Jackson State | B266: Auburn | C266: -30.5 | D266: TRUE | E266: 0.995 | F266: Y | G266: 45980
A267: Loyola MD | B267: Duquesne | C267: -13.5 | D267: TRUE | E267: 0.9925 | F267: Y | G267: 45980
A268: Bellarmine | B268: Notre Dame | C268: -27 | D268: TRUE | E268: 0.985 | F268: N | G268: 45980
A269: UMass Lowell | B269: Bradley | C269: -19.5 | D269: TRUE | E269: 0.9825 | F269: N | G269: 45980
A270: Dayton | B270: Marquette | C270: -5.5 | D270: TRUE | E270: 0.88 | F270: N | G270: 45980
...

Sheet Model Record
B1: 2025 TOTAL RECORD
B2: =16+COUNTIF(Games!M:M, "Y")&"-"& COUNTIF(Games!M:M, "N")-16 -> 176-136
B3: =IFERROR((16+COUNTIF(Games!M:M,"Y"))/(16+COUNTIF(Games!M:M,"Y")+COUNTIF(Games!M:M,"N")-16),"NA") -> 0.56410256
C5: 1 | D5: 99%-99.9% | E5: 95-99% | F5: 93-95% | G5: 90-93% | H5: 85-90% | I5: 80-85% | J5: 75-80% | K5: 70-75% | L5: 65-70% | M5: 60-65% | N5: 55-60% | O5: 50-55%
C6: =COUNTIFS(Games!E:E,1,Games!M:M,"Y") & "-" & COUNTIFS(Games!E:E,1,Games!M:M,"N") -> 8-2 | D6: =COUNTIFS(Games!E:E,">=.99",Games!E:E,"<1",Games!M:M,"Y") & "-" & COUNTIFS(Games!E:E,">=.99",Games!E:E,"<1",Games!M:M,"N") -> 17-13 | E6: =COUNTIFS(Games!E:E,">=0.95",Games!M:M,"Y",Games!E:E, "<0.99",Games!M:M,"Y") & "-" & COUNTIFS(Games!E:E,">=0.95",Games!M:M,"N",Games!E:E, "<0.99",Games!M:M,"N") -> 21-21 | F6: =COUNTIFS(Games!E:E,">=0.93",Games!M:M,"Y",Games!E:E, "<0.95",Games!M:M,"Y") & "-" & COUNTIFS(Games!E:E,">=0.93",Games!M:M,"N",Games!E:E, "<0.95",Games!M:M,"N") -> 9-12 | G6: =COUNTIFS(Games!E:E,">=0.9",Games!M:M,"Y",Games!E:E, "<0.93",Games!M:M,"Y") & "-" & COUNTIFS(Games!E:E,">=0.9",Games!M:M,"N",Games!E:E, "<0.93",Games!M:M,"N") -> 11-5 | H6: =COUNTIFS(Games!E:E,">=0.85",Games!M:M,"Y",Games!E:E, "<0.9",Games!M:M,"Y") & "-" & COUNTIFS(Games!E:E,">=0.85",Games!M:M,"N",Games!E:E, "<0.9",Games!M:M,"N") -> 12-28 | I6: =COUNTIFS(Games!E:E,">=0.8",Games!M:M,"Y",Games!E:E, "<0.85",Games!M:M,"Y") & "-" & COUNTIFS(Games!E:E,">=0.8",Games!M:M,"N",Games!E:E, "<0.85",Games!M:M,"N") -> 17-19 | J6: =COUNTIFS(Games!E:E,">=0.75",Games!M:M,"Y",Games!E:E, "<0.8",Games!M:M,"Y") & "-" & COUNTIFS(Games!E:E,">=0.75",Games!M:M,"N",Games!E:E, "<0.8",Games!M:M,"N") -> 8-5 | K6: =COUNTIFS(Games!E:E,">=0.7",Games!M:M,"Y",Games!E:E, "<0.75",Games!M:M,"Y") & "-" & COUNTIFS(Games!E:E,">=0.7",Games!M:M,"N",Games!E:E, "<0.75",Games!M:M,"N") -> 9-11 | L6: =COUNTIFS(Games!E:E,">=0.65",Games!M:M,"Y",Games!E:E, "<0.7",Games!M:M,"Y") & "-" & COUNTIFS(Games!E:E,">=0.65",Games!M:M,"N",Games!E:E, "<0.7",Games!M:M,"N") -> 16-6 | M6: =COUNTIFS(Games!E:E,">=0.6",Games!M:M,"Y",Games!E:E, "<.65",Games!M:M,"Y") & "-" & COUNTIFS(Games!E:E,">=0.6",Games!M:M,"N",Games!E:E, "<0.65",Games!M:M,"N") -> 10-11 | N6: =COUNTIFS(Games!E:E,">=0.55",Games!M:M,"Y",Games!E:E, "<.6",Games!M:M,"Y") & "-" & COUNTIFS(Games!E:E,">=0.55",Games!M:M,"N",Games!E:E, "<0.6",Games!M:M,"N") -> 15-5 | O6: =COUNTIFS(Games!E:E,">=0.5",Games!M:M,"Y",Games!E:E, "<.55",Games!M:M,"Y") & "-" & COUNTIFS(Games!E:E,">=0.5",Games!M:M,"N",Games!E:E, "<0.55",Games!M:M,"N") -> 7-14
C7: =IFERROR(LEFT(C6)/SUM(LEFT(C6),RIGHT(C6)), "NA") -> 0.8 | D7: =IFERROR(LEFT(D6,2)/SUM(LEFT(D6,2),RIGHT(D6,2)), "NA") -> 0.56666667 | E7: =IFERROR(LEFT(E6,2)/SUM(LEFT(E6,2),RIGHT(E6,2)), "NA") -> 0.5 | F7: =IFERROR(LEFT(F6,1)/SUM(LEFT(F6),RIGHT(F6,2)), "NA") -> 0.42857143 | G7: =IFERROR(LEFT(G6,2)/SUM(LEFT(G6,2),RIGHT(G6)), "NA") -> 0.6875 | H7: =IFERROR(LEFT(H6,2)/SUM(LEFT(H6,2),RIGHT(H6,2)), "NA") -> 0.3 | I7: =IFERROR(LEFT(I6,2)/SUM(LEFT(I6,2),RIGHT(I6,2)), "NA") -> 0.47222222 | J7: =IFERROR(LEFT(J6,1)/SUM(LEFT(J6),RIGHT(J6)), "NA") -> 0.61538462 | K7: =IFERROR(LEFT(K6,1)/SUM(LEFT(K6),RIGHT(K6,2)), "NA") -> 0.45 | L7: =IFERROR(LEFT(L6,2)/SUM(LEFT(L6,2),RIGHT(L6)), "NA") -> 0.72727273 | M7: =IFERROR(LEFT(M6,2)/SUM(LEFT(M6,2),RIGHT(M6,2)), "NA") -> 0.47619048 | N7: =IFERROR(LEFT(N6,2)/SUM(LEFT(N6,2),RIGHT(N6)), "NA") -> 0.75 | O7: =IFERROR(LEFT(O6,1)/SUM(LEFT(O6),RIGHT(O6,2)), "NA") -> 0.33333333
B9: Units | C9: 5 | D9: 0.5 | E9: 0.5 | F9: 0.5 | G9: 3 | H9: 3 | I9: 0.5 | J9: 1.5 | K9: 1.5 | L9: 1 | M9: 1.5 | N9: 1.5 | O9: 1.5
B10: Return | C10: =C9*(LEFT(C6,1)-(1.1*RIGHT(C6,1))) -> 29 | D10: =D9*(LEFT(D6,2)-(1.1*RIGHT(D6,2))) -> 1.35 | E10: =E9*(LEFT(E6,2)-(1.1*RIGHT(E6,2))) -> -1.05 | F10: =F9*(LEFT(F6,1)-(1.1*RIGHT(F6,2))) -> -2.1 | G10: =G9*(LEFT(G6,2)-(1.1*RIGHT(G6,1))) -> 16.5 | H10: =-H9*(LEFT(H6,2)-(1.1*RIGHT(H6,2))) -> 56.4 | I10: =I9*(LEFT(I6,2)-(1.1*RIGHT(I6,2))) -> -1.95 | J10: =J9*(LEFT(J6,1)-(1.1*RIGHT(J6,1))) -> 3.75 | K10: =K9*(LEFT(K6,1)-(1.1*RIGHT(K6,2))) -> -4.65 | L10: =L9*(LEFT(L6,2)-(1.1*RIGHT(L6,1))) -> 9.4 | M10: =M9*(LEFT(M6,2)-(1.1*RIGHT(M6,2))) -> -3.15 | N10: =N9*(LEFT(N6,2)-(1.1*RIGHT(N6,1))) -> 14.25 | O10: =-O9*(LEFT(O6,1)-(1.1*RIGHT(O6,2))) -> 12.6 | P10: =SUM(D10:O10) -> 101.35
E13: **52.38% + is beating vegas

Sheet Games
A1: Away_Team | B1: Home_Team | C1: Spread | D1: Will_Cover | E1: Confidence | F1: Home_ORtg | G1: Home_DRtg | H1: Home_AdjT | I1: Away_ORtg | J1: Away_DRtg | K1: Away_AdjT | L1: NetRtg_Diff | M1: Result | N1: Date | O1: Confidence % | Q1: CI LEVEL | R1: RECORD | S1: SUCCESS RATE | T1: UNITS | U1: RETURN
A2: Green Bay | B2: Kansas | C2: -29 | D2: TRUE | E2: 1 | F2: 115.9 | G2: 93.4 | H2: 71.4 | I2: 98.9 | J2: 113 | K2: 71.5 | L2: 36.58 | N2: 45964 | O2: {=_xlfn.IFS(E36=1,$S$2,E36>=0.99,$S$3, E36>=0.95,$S$4, E36>= 0.93, $S$5, E36>= 0.9,$S$6, E36>= 0.85,$S$7, E36>= 0.8,$S$8, E36>= 0.75,$S$9, E36 >= 0.7, $S$10, E36>= 0.65, $S$11, E36>= 0.6, $S$12, E36>= 0.55,$S$13, E36 >= 0.5,$S$14)} -> 0.5 | Q2: 1 | R2: =COUNTIFS($E:E, "=1", M:M, "Y") & "-" & COUNTIFS(E:E, "=1", M:M, "N") -> 8-2 | S2: =IFERROR(LEFT(R2)/SUM(LEFT(R2),RIGHT(R2)), "NA") -> 0.8 | T2: 5 | U2: =T2*(LEFT(R2,1)-(1.1*RIGHT(R2,1))) -> 29
A3: Canisius | B3: Dayton | C3: -24.5 | D3: TRUE | E3: 1 | F3: 113.1 | G3: 96.9 | H3: 69 | I3: 96 | J3: 112.5 | K3: 70.6 | L3: 32.69 | N3: 45964 | O3: {=_xlfn.IFS(E37=1,$S$2,E37>=0.99,$S$3, E37>=0.95,$S$4, E37>= 0.93, $S$5, E37>= 0.9,$S$6, E37>= 0.85,$S$7, E37>= 0.8,$S$8, E37>= 0.75,$S$9, E37 >= 0.7, $S$10, E37>= 0.65, $S$11, E37>= 0.6, $S$12, E37>= 0.55,$S$13, E37 >= 0.5,$S$14)} -> 0.8 | Q3: 99-99.9% | R3: =COUNTIFS($E:E, ">=.99",$E:E, "<1", M:M, "Y") & "-" & COUNTIFS(E:E, ">=.99", $E:E, "<1", M:M, "N") -> 17-13 | S3: =IFERROR(LEFT(R3,2)/SUM(LEFT(R3,2),RIGHT(R3,2)), "NA") -> 0.56666667 | T3: 2 | U3: =T3*(LEFT(R3,2)-(1.1*RIGHT(R3,2))) -> 5.4
A4: Cal Poly | B4: USC | C4: -25 | D4: TRUE | E4: 1 | F4: 116.5 | G4: 94.9 | H4: 73.9 | I4: 101.6 | J4: 109.6 | K4: 77.3 | L4: 29.63 | N4: 45964 | O4: {=_xlfn.IFS(E38=1,$S$2,E38>=0.99,$S$3, E38>=0.95,$S$4, E38>= 0.93, $S$5, E38>= 0.9,$S$6, E38>= 0.85,$S$7, E38>= 0.8,$S$8, E38>= 0.75,$S$9, E38 >= 0.7, $S$10, E38>= 0.65, $S$11, E38>= 0.6, $S$12, E38>= 0.55,$S$13, E38 >= 0.5,$S$14)} -> 0.8 | Q4: 95-99% | R4: =COUNTIFS(E:E, ">=.95",E:E, "<.99", M:M, "Y") & "-" & COUNTIFS(E:E, ">=.95",E:E, "<.99", M:M, "N") -> 21-21 | S4: =IFERROR(LEFT(R4,2)/SUM(LEFT(R4,2),RIGHT(R4,2)), "NA") -> 0.5 | T4: 0.5 | U4: =T4*(LEFT(R4,2)-(1.1*RIGHT(R4,2))) -> -1.05
A5: Rider | B5: Virginia | C5: -25 | D5: TRUE | E5: 1 | F5: 114.9 | G5: 99.5 | H5: 69.4 | I5: 99.2 | J5: 111.4 | K5: 69.5 | L5: 27.57 | N5: 45964 | O5: {=_xlfn.IFS(E39=1,$S$2,E39>=0.99,$S$3, E39>=0.95,$S$4, E39>= 0.93, $S$5, E39>= 0.9,$S$6, E39>= 0.85,$S$7, E39>= 0.8,$S$8, E39>= 0.75,$S$9, E39 >= 0.7, $S$10, E39>= 0.65, $S$11, E39>= 0.6, $S$12, E39>= 0.55,$S$13, E39 >= 0.5,$S$14)} -> 0.56666667 | Q5: 93-95% | R5: =COUNTIFS(E:E, ">=.93",E:E, "<.95", M:M, "Y") & "-" & COUNTIFS(E:E, ">=.93",E:E, "<.95", M:M, "N") -> 9-12 | S5: =IFERROR(LEFT(R5,1)/SUM(LEFT(R5),RIGHT(R5,2)), "NA") -> 0.42857143 | T5: 1.5 | U5: =T5*(LEFT(R5,1)-(1.1*RIGHT(R5,2))) -> -6.3
A6: North Dakota | B6: Alabama | C6: -31.5 | D6: TRUE | E6: 0.9975 | F6: 117.9 | G6: 96.7 | H6: 76.4 | I6: 101.1 | J6: 113.2 | K6: 71.9 | L6: 33.16 | N6: 45964 | O6: {=_xlfn.IFS(E40=1,$S$2,E40>=0.99,$S$3, E40>=0.95,$S$4, E40>= 0.93, $S$5, E40>= 0.9,$S$6, E40>= 0.85,$S$7, E40>= 0.8,$S$8, E40>= 0.75,$S$9, E40 >= 0.7, $S$10, E40>= 0.65, $S$11, E40>= 0.6, $S$12, E40>= 0.55,$S$13, E40 >= 0.5,$S$14)} -> 0.56666667 | Q6: 90-93% | R6: =COUNTIFS(E:E, ">=.9",E:E, "<.93", M:M, "Y") & "-" & COUNTIFS(E:E, ">=.9",E:E, "<.93", M:M, "N") -> 11-5 | S6: =IFERROR(LEFT(R6,2)/SUM(LEFT(R6,2),RIGHT(R6)), "NA") -> 0.6875 | T6: 3 | U6: =T6*(LEFT(R6,1)-(1.1*RIGHT(R6,1))) -> -13.5
A7: Air Force | B7: Belmont | C7: -16 | D7: TRUE | E7: 0.9975 | F7: 109.2 | G7: 103.1 | H7: 73.3 | I7: 100.5 | J7: 108.9 | K7: 67.9 | L7: 14.62 | N7: 45964 | O7: {=_xlfn.IFS(E41=1,$S$2,E41>=0.99,$S$3, E41>=0.95,$S$4, E41>= 0.93, $S$5, E41>= 0.9,$S$6, E41>= 0.85,$S$7, E41>= 0.8,$S$8, E41>= 0.75,$S$9, E41 >= 0.7, $S$10, E41>= 0.65, $S$11, E41>= 0.6, $S$12, E41>= 0.55,$S$13, E41 >= 0.5,$S$14)} -> 0.56666667 | Q7: 85-90% | R7: =COUNTIFS(E:E, ">=.85",E:E, "<.9", M:M, "Y") & "-" & COUNTIFS(E:E, ">=.85",E:E, "<.9", $M:M, "N") -> 12-28 | S7: =IFERROR(LEFT(R7,2)/SUM(LEFT(R7,2),RIGHT(R7,2)), "NA") -> 0.3 | T7: 3 | U7: =T7*((RIGHT(R7,2)-(1.1*LEFT(R7,2)))) -> 44.4
A8: Oakland | B8: Michigan | C8: -23 | D8: TRUE | E8: 0.995 | F8: 119.2 | G8: 93.5 | H8: 74.1 | I8: 106 | J8: 110.6 | K8: 70.8 | L8: 30.29 | N8: 45964 | O8: {=_xlfn.IFS(E42=1,$S$2,E42>=0.99,$S$3, E42>=0.95,$S$4, E42>= 0.93, $S$5, E42>= 0.9,$S$6, E42>= 0.85,$S$7, E42>= 0.8,$S$8, E42>= 0.75,$S$9, E42 >= 0.7, $S$10, E42>= 0.65, $S$11, E42>= 0.6, $S$12, E42>= 0.55,$S$13, E42 >= 0.5,$S$14)} -> 0.56666667 | Q8: 80-85% | R8: =COUNTIFS(E:E,">=.8",E:E,"<.85",M:M,"Y")&"-"&COUNTIFS(E:E,">=.8",E:E,"<0.85",M:M,"N") -> 17-19 | S8: =IFERROR(LEFT(R8,2)/SUM(LEFT(R8,2),RIGHT(R8,2)), "NA") -> 0.47222222 | T8: 0.5 | U8: =T8*(LEFT(R8,2)-(1.1*RIGHT(R8,2))) -> -1.95
A9: Campbell | B9: Wisconsin | C9: -20 | D9: TRUE | E9: 0.995 | F9: 119 | G9: 96.3 | H9: 71.3 | I9: 103.2 | J9: 108.4 | K9: 71.3 | L9: 27.79 | N9: 45964 | O9: {=_xlfn.IFS(E43=1,$S$2,E43>=0.99,$S$3, E43>=0.95,$S$4, E43>= 0.93, $S$5, E43>= 0.9,$S$6, E43>= 0.85,$S$7, E43>= 0.8,$S$8, E43>= 0.75,$S$9, E43 >= 0.7, $S$10, E43>= 0.65, $S$11, E43>= 0.6, $S$12, E43>= 0.55,$S$13, E43 >= 0.5,$S$14)} -> 0.56666667 | Q9: 75-80% | R9: =COUNTIFS(E:E, ">=.75",E:E, "<.8", M:M, "Y") & "-" & COUNTIFS(E:E, ">=.75",E:E, "<.8", M:M, "N") -> 8-5 | S9: =IFERROR(LEFT(R9,1)/SUM(LEFT(R9),RIGHT(R9)), "NA") -> 0.61538462 | T9: 1.5 | U9: =T9*(LEFT(R9,1)-(1.1*RIGHT(R9,1))) -> 3.75
A10: Saint Peter's | B10: Seton Hall | C10: -14.5 | D10: TRUE | E10: 0.995 | F10: 107.5 | G10: 97.3 | H10: 68.8 | I10: 97.2 | J10: 108.3 | K10: 67.9 | L10: 21.2 | N10: 45964 | O10: {=_xlfn.IFS(E44=1,$S$2,E44>=0.99,$S$3, E44>=0.95,$S$4, E44>= 0.93, $S$5, E44>= 0.9,$S$6, E44>= 0.85,$S$7, E44>= 0.8,$S$8, E44>= 0.75,$S$9, E44 >= 0.7, $S$10, E44>= 0.65, $S$11, E44>= 0.6, $S$12, E44>= 0.55,$S$13, E44 >= 0.5,$S$14)} -> 0.56666667 | Q10: 70-75% | R10: =COUNTIFS(E:E, ">=.7",E:E, "<.75", M:M, "Y") & "-" & COUNTIFS(E:E, ">=.7",E:E, "<.75", M:M, "N") -> 9-11 | S10: =IFERROR(LEFT(R10,1)/SUM(LEFT(R10),RIGHT(R10,2)), "NA") -> 0.45 | T10: 1 | U10: =T10*(LEFT(R10,1)-(1.1*RIGHT(R10,1))) -> 7.9
A11: Wofford | B11: George Mason | C11: -13.5 | D11: TRUE | E11: 0.995 | F11: 108.1 | G11: 98 | H11: 68.9 | I11: 102 | J11: 108.9 | K11: 70.1 | L11: 16.95 | N11: 45964 | O11: {=_xlfn.IFS(E45=1,$S$2,E45>=0.99,$S$3, E45>=0.95,$S$4, E45>= 0.93, $S$5, E45>= 0.9,$S$6, E45>= 0.85,$S$7, E45>= 0.8,$S$8, E45>= 0.75,$S$9, E45 >= 0.7, $S$10, E45>= 0.65, $S$11, E45>= 0.6, $S$12, E45>= 0.55,$S$13, E45 >= 0.5,$S$14)} -> 0.56666667 | Q11: 65-70% | R11: =COUNTIFS(E:E, ">=.65",E:E, "<.7", M:M, "Y") & "-" & COUNTIFS(E:E, ">=.65",E:E, "<.7", M:M, "N") -> 16-6 | S11: =IFERROR(LEFT(R11,2)/SUM(LEFT(R11,2),RIGHT(R11)), "NA") -> 0.72727273 | T11: 3 | U11: =T11*(LEFT(R11,2)-(1.1*RIGHT(R11,1))) -> 28.2
A12: Fairfield | B12: Penn State | C12: -16 | D12: TRUE | E12: 0.9925 | F12: 107.9 | G12: 101.3 | H12: 72.7 | I12: 100.8 | J12: 111.1 | K12: 70.9 | L12: 17.01 | N12: 45964 | O12: {=_xlfn.IFS(E46=1,$S$2,E46>=0.99,$S$3, E46>=0.95,$S$4, E46>= 0.93, $S$5, E46>= 0.9,$S$6, E46>= 0.85,$S$7, E46>= 0.8,$S$8, E46>= 0.75,$S$9, E46 >= 0.7, $S$10, E46>= 0.65, $S$11, E46>= 0.6, $S$12, E46>= 0.55,$S$13, E46 >= 0.5,$S$14)} -> 0.5 | Q12: 60-65% | R12: =COUNTIFS(E:E, ">=.6",E:E, "<.65", M:M, "Y") & "-" & COUNTIFS(E:E, ">=.6",E:E, "<.65", M:M, "N") -> 10-11 | S12: =IFERROR(LEFT(R12,2)/SUM(LEFT(R12,2),RIGHT(R12,2)), "NA") -> 0.47619048 | T12: 0.5 | U12: =T12*(LEFT(R12,2)-(1.1*RIGHT(R12,2))) -> -1.05
A13: Colgate | B13: Michigan State | C13: -20.5 | D13: TRUE | E13: 0.9925 | F13: 115 | G13: 95.6 | H13: 70.9 | I13: 104.5 | J13: 107.3 | K13: 71.4 | L13: 22.16 | N13: 45964 | O13: {=_xlfn.IFS(E47=1,$S$2,E47>=0.99,$S$3, E47>=0.95,$S$4, E47>= 0.93, $S$5, E47>= 0.9,$S$6, E47>= 0.85,$S$7, E47>= 0.8,$S$8, E47>= 0.75,$S$9, E47 >= 0.7, $S$10, E47>= 0.65, $S$11, E47>= 0.6, $S$12, E47>= 0.55,$S$13, E47 >= 0.5,$S$14)} -> 0.5 | Q13: 55-60% | R13: =COUNTIFS(E:E, ">=.55",E:E, "<.6", M:M, "Y") & "-" & COUNTIFS(E:E, ">=.55",E:E, "<.6", M:M, "N") -> 15-5 | S13: =IFERROR(LEFT(R13,2)/SUM(LEFT(R13,2),RIGHT(R13)), "NA") -> 0.75 | T13: 2 | U13: =T13*(LEFT(R13,2)-(1.1*RIGHT(R13,1))) -> 19
A14: Montana State | B14: Colorado | C14: -13 | D14: TRUE | E14: 0.9925 | F14: 109.9 | G14: 101.7 | H14: 71.5 | I14: 104.6 | J14: 110.2 | K14: 70.7 | L14: 13.78 | N14: 45964 | O14: {=_xlfn.IFS(E48=1,$S$2,E48>=0.99,$S$3, E48>=0.95,$S$4, E48>= 0.93, $S$5, E48>= 0.9,$S$6, E48>= 0.85,$S$7, E48>= 0.8,$S$8, E48>= 0.75,$S$9, E48 >= 0.7, $S$10, E48>= 0.65, $S$11, E48>= 0.6, $S$12, E48>= 0.55,$S$13, E48 >= 0.5,$S$14)} -> 0.5 | Q14: 50-55% | R14: =COUNTIFS(E:E, ">=.5",E:E, "<.55", M:M, "Y") & "-" & COUNTIFS(E:E, ">=.5",E:E, "<.55", M:M, "N") -> 7-14 | S14: =IFERROR(LEFT(R14,1)/SUM(LEFT(R14),RIGHT(R14,2)), "NA") -> 0.33333333 | T14: 0.5 | U14: =T14*(LEFT(R14,1)-(1.1*RIGHT(R14,2))) -> -4.2
A15: San Jose State | B15: Utah | C15: -12.5 | D15: TRUE | E15: 0.99 | F15: 111.6 | G15: 101.1 | H15: 72.1 | I15: 105.7 | J15: 106.1 | K15: 70.4 | L15: 10.84 | N15: 45964 | O15: {=_xlfn.IFS(E49=1,$S$2,E49>=0.99,$S$3, E49>=0.95,$S$4, E49>= 0.93, $S$5, E49>= 0.9,$S$6, E49>= 0.85,$S$7, E49>= 0.8,$S$8, E49>= 0.75,$S$9, E49 >= 0.7, $S$10, E49>= 0.65, $S$11, E49>= 0.6, $S$12, E49>= 0.55,$S$13, E49 >= 0.5,$S$14)} -> 0.5
A16: Youngstown State | B16: Pitt | C16: -13.5 | D16: TRUE | E16: 0.985 | F16: 112.7 | G16: 99.3 | H16: 69.6 | I16: 103.2 | J16: 105.9 | K16: 71.9 | L16: 16.07 | N16: 45964 | O16: {=_xlfn.IFS(E50=1,$S$2,E50>=0.99,$S$3, E50>=0.95,$S$4, E50>= 0.93, $S$5, E50>= 0.9,$S$6, E50>= 0.85,$S$7, E50>= 0.8,$S$8, E50>= 0.75,$S$9, E50 >= 0.7, $S$10, E50>= 0.65, $S$11, E50>= 0.6, $S$12, E50>= 0.55,$S$13, E50 >= 0.5,$S$14)} -> 0.5 | T16: TOTAL | U16: =SUM(U2:U14) -> 109.6
A17: Niagara | B17: Duquesne | C17: -15.5 | D17: TRUE | E17: 0.9825 | F17: 106.6 | G17: 101 | H17: 70.7 | I17: 97.4 | J17: 112.4 | K17: 70.3 | L17: 20.67 | N17: 45964 | O17: {=_xlfn.IFS(E51=1,$S$2,E51>=0.99,$S$3, E51>=0.95,$S$4, E51>= 0.93, $S$5, E51>= 0.9,$S$6, E51>= 0.85,$S$7, E51>= 0.8,$S$8, E51>= 0.75,$S$9, E51 >= 0.7, $S$10, E51>= 0.65, $S$11, E51>= 0.6, $S$12, E51>= 0.55,$S$13, E51 >= 0.5,$S$14)} -> 0.42857143
A18: Mercer | B18: Tennessee | C18: -28 | D18: TRUE | E18: 0.9775 | F18: 115.3 | G18: 91.5 | H18: 69.3 | I18: 101.2 | J18: 106.1 | K18: 74.2 | L18: 28.68 | N18: 45964 | O18: {=_xlfn.IFS(E52=1,$S$2,E52>=0.99,$S$3, E52>=0.95,$S$4, E52>= 0.93, $S$5, E52>= 0.9,$S$6, E52>= 0.85,$S$7, E52>= 0.8,$S$8, E52>= 0.75,$S$9, E52 >= 0.7, $S$10, E52>= 0.65, $S$11, E52>= 0.6, $S$12, E52>= 0.55,$S$13, E52 >= 0.5,$S$14)} -> 0.42857143
A19: Hofstra | B19: UCF | C19: -11 | D19: TRUE | E19: 0.9775 | F19: 111.5 | G19: 100.4 | H19: 74.2 | I19: 104 | J19: 103.7 | K19: 69.8 | L19: 10.86 | N19: 45964 | O19: {=_xlfn.IFS(E53=1,$S$2,E53>=0.99,$S$3, E53>=0.95,$S$4, E53>= 0.93, $S$5, E53>= 0.9,$S$6, E53>= 0.85,$S$7, E53>= 0.8,$S$8, E53>= 0.75,$S$9, E53 >= 0.7, $S$10, E53>= 0.65, $S$11, E53>= 0.6, $S$12, E53>= 0.55,$S$13, E53 >= 0.5,$S$14)} -> 0.42857143
A20: Samford | B20: Tulane | C20: -7.5 | D20: TRUE | E20: 0.975 | F20: 111.3 | G20: 105.6 | H20: 71.1 | I20: 106.5 | J20: 110.3 | K20: 70.6 | L20: 9.42 | N20: 45964 | O20: {=_xlfn.IFS(E54=1,$S$2,E54>=0.99,$S$3, E54>=0.95,$S$4, E54>= 0.93, $S$5, E54>= 0.9,$S$6, E54>= 0.85,$S$7, E54>= 0.8,$S$8, E54>= 0.75,$S$9, E54 >= 0.7, $S$10, E54>= 0.65, $S$11, E54>= 0.6, $S$12, E54>= 0.55,$S$13, E54 >= 0.5,$S$14)} -> 0.6875
A21: Detroit Mercy | B21: Illinois Chicago | C21: -9.5 | D21: TRUE | E21: 0.9725 | F21: 105.4 | G21: 102.9 | H21: 73.4 | I21: 99.3 | J21: 110.6 | K21: 72.2 | L21: 13.73 | N21: 45964 | O21: {=_xlfn.IFS(E55=1,$S$2,E55>=0.99,$S$3, E55>=0.95,$S$4, E55>= 0.93, $S$5, E55>= 0.9,$S$6, E55>= 0.85,$S$7, E55>= 0.8,$S$8, E55>= 0.75,$S$9, E55 >= 0.7, $S$10, E55>= 0.65, $S$11, E55>= 0.6, $S$12, E55>= 0.55,$S$13, E55 >= 0.5,$S$14)} -> 0.6875
A22: IU Indy | B22: Ohio State | C22: -31 | D22: TRUE | E22: 0.9675 | F22: 119.8 | G22: 101.4 | H22: 74 | I22: 101.1 | J22: 116.3 | K22: 73.4 | L22: 33.64 | N22: 45964 | O22: {=_xlfn.IFS(E56=1,$S$2,E56>=0.99,$S$3, E56>=0.95,$S$4, E56>= 0.93, $S$5, E56>= 0.9,$S$6, E56>= 0.85,$S$7, E56>= 0.8,$S$8, E56>= 0.75,$S$9, E56 >= 0.7, $S$10, E56>= 0.65, $S$11, E56>= 0.6, $S$12, E56>= 0.55,$S$13, E56 >= 0.5,$S$14)} -> 0.6875
A23: Marist | B23: Xavier | C23: -11 | D23: TRUE | E23: 0.9525 | F23: 110.8 | G23: 99.2 | H23: 74 | I23: 98.2 | J23: 101 | K23: 68.5 | L23: 14.39 | N23: 45964 | O23: {=_xlfn.IFS(E57=1,$S$2,E57>=0.99,$S$3, E57>=0.95,$S$4, E57>= 0.93, $S$5, E57>= 0.9,$S$6, E57>= 0.85,$S$7, E57>= 0.8,$S$8, E57>= 0.75,$S$9, E57 >= 0.7, $S$10, E57>= 0.65, $S$11, E57>= 0.6, $S$12, E57>= 0.55,$S$13, E57 >= 0.5,$S$14)} -> 0.3
A24: Old Dominion | B24: Miami OH | C24: -6.5 | D24: TRUE | E24: 0.8775 | F24: 107.8 | G24: 104.6 | H24: 73.1 | I24: 104.6 | J24: 108.9 | K24: 71.3 | L24: 7.52 | N24: 45964 | O24: {=_xlfn.IFS(E58=1,$S$2,E58>=0.99,$S$3, E58>=0.95,$S$4, E58>= 0.93, $S$5, E58>= 0.9,$S$6, E58>= 0.85,$S$7, E58>= 0.8,$S$8, E58>= 0.75,$S$9, E58 >= 0.7, $S$10, E58>= 0.65, $S$11, E58>= 0.6, $S$12, E58>= 0.55,$S$13, E58 >= 0.5,$S$14)} -> 0.3
A25: Denver | B25: Seattle | C25: -11.5 | D25: TRUE | E25: 0.8625 | F25: 103.9 | G25: 101 | H25: 72.3 | I25: 98.8 | J25: 113.1 | K25: 72.5 | L25: 17.21 | N25: 45964 | O25: {=_xlfn.IFS(E59>=0.99,$S$3, E59>=0.95,$S$4, E59>= 0.93, $S$5, E59>= 0.9,$S$6, E59>= 0.85,$S$7, E59>= 0.8,$S$8, E59>= 0.75,$S$9, E59 >= 0.7, $S$10, E59>= 0.65, $S$11, E59>= 0.6, $S$12, E59>= 0.55,$S$13, E59 >= 0.5,$S$14)} -> 0.3
A26: Idaho | B26: Washington State | C26: -8 | D26: TRUE | E26: 0.8425 | F26: 106.8 | G26: 107.3 | H26: 73.8 | I26: 106.6 | J26: 111.3 | K26: 70.4 | L26: 4.33 | N26: 45964 | O26: {=_xlfn.IFS(E60>=0.99,$S$3, E60>=0.95,$S$4, E60>= 0.93, $S$5, E60>= 0.9,$S$6, E60>= 0.85,$S$7, E60>= 0.8,$S$8, E60>= 0.75,$S$9, E60 >= 0.7, $S$10, E60>= 0.65, $S$11, E60>= 0.6, $S$12, E60>= 0.55,$S$13, E60 >= 0.5,$S$14)} -> 0.47222222
A27: Troy | B27: Kent State | C27: -3.5 | D27: TRUE | E27: 0.755 | F27: 108.2 | G27: 106.8 | H27: 72.1 | I27: 107.6 | J27: 103.5 | K27: 72.4 | L27: -2.78 | N27: 45964 | O27: {=_xlfn.IFS(E61>=0.99,$S$3, E61>=0.95,$S$4, E61>= 0.93, $S$5, E61>= 0.9,$S$6, E61>= 0.85,$S$7, E61>= 0.8,$S$8, E61>= 0.75,$S$9, E61 >= 0.7, $S$10, E61>= 0.65, $S$11, E61>= 0.6, $S$12, E61>= 0.55,$S$13, E61 >= 0.5,$S$14)} -> 0.47222222
A28: Arkansas State | B28: Ohio | C28: -3.5 | D28: TRUE | E28: 0.6775 | F28: 106.6 | G28: 108.2 | H28: 73.6 | I28: 106.4 | J28: 105 | K28: 72.8 | L28: -2.99 | N28: 45964 | O28: {=_xlfn.IFS(E62>=0.99,$S$3, E62>=0.95,$S$4, E62>= 0.93, $S$5, E62>= 0.9,$S$6, E62>= 0.85,$S$7, E62>= 0.8,$S$8, E62>= 0.75,$S$9, E62 >= 0.7, $S$10, E62>= 0.65, $S$11, E62>= 0.6, $S$12, E62>= 0.55,$S$13, E62 >= 0.5,$S$14)} -> 0.61538462
A29: Marshall | B29: Massachusetts | C29: -4.5 | D29: TRUE | E29: 0.665 | F29: 100.7 | G29: 105.6 | H29: 75.2 | I29: 102.9 | J29: 105.1 | K29: 73.8 | L29: -2.68 | N29: 45964 | O29: {=_xlfn.IFS(E63>=0.99,$S$3, E63>=0.95,$S$4, E63>= 0.93, $S$5, E63>= 0.9,$S$6, E63>= 0.85,$S$7, E63>= 0.8,$S$8, E63>= 0.75,$S$9, E63 >= 0.7, $S$10, E63>= 0.65, $S$11, E63>= 0.6, $S$12, E63>= 0.55,$S$13, E63 >= 0.5,$S$14)} -> 0.45
A30: Boston College | B30: Florida Atlantic | C30: -1.5 | D30: TRUE | E30: 0.6475 | F30: 107.3 | G30: 105.6 | H30: 72.6 | I30: 108.7 | J30: 101.4 | K30: 70.8 | L30: -5.61 | N30: 45964 | O30: {=_xlfn.IFS(E64>=0.99,$S$3, E64>=0.95,$S$4, E64>= 0.93, $S$5, E64>= 0.9,$S$6, E64>= 0.85,$S$7, E64>= 0.8,$S$8, E64>= 0.75,$S$9, E64 >= 0.7, $S$10, E64>= 0.65, $S$11, E64>= 0.6, $S$12, E64>= 0.55,$S$13, E64 >= 0.5,$S$14)} -> 0.45
A31: Hampton | B31: Milwaukee | C31: -5.5 | D31: TRUE | E31: 0.64 | F31: 104.5 | G31: 109.1 | H31: 74.1 | I31: 102.2 | J31: 107.5 | K31: 71.9 | L31: 0.71 | N31: 45964 | O31: {=_xlfn.IFS(E65>=0.99,$S$3, E65>=0.95,$S$4, E65>= 0.93, $S$5, E65>= 0.9,$S$6, E65>= 0.85,$S$7, E65>= 0.8,$S$8, E65>= 0.75,$S$9, E65 >= 0.7, $S$10, E65>= 0.65, $S$11, E65>= 0.6, $S$12, E65>= 0.55,$S$13, E65 >= 0.5,$S$14)} -> 0.72727273
A32: Louisiana | B32: Ball State | C32: -2.5 | D32: FALSE | E32: 0.6 | F32: 104.6 | G32: 110.2 | H32: 70 | I32: 103 | J32: 109.5 | K32: 70.2 | L32: 0.9 | N32: 45964 | O32: {=_xlfn.IFS(E66>=0.99,$S$3, E66>=0.95,$S$4, E66>= 0.93, $S$5, E66>= 0.9,$S$6, E66>= 0.85,$S$7, E66>= 0.8,$S$8, E66>= 0.75,$S$9, E66 >= 0.7, $S$10, E66>= 0.65, $S$11, E66>= 0.6, $S$12, E66>= 0.55,$S$13, E66 >= 0.5,$S$14)} -> 0.72727273
A33: Utah Tech | B33: South Dakota | C33: -2.5 | D33: TRUE | E33: 0.5825 | F33: 101.6 | G33: 112.9 | H33: 75.1 | I33: 99.7 | J33: 106.5 | K33: 72.1 | L33: -4.43 | N33: 45964 | O33: {=_xlfn.IFS(E67>=0.99,$S$3, E67>=0.95,$S$4, E67>= 0.93, $S$5, E67>= 0.9,$S$6, E67>= 0.85,$S$7, E67>= 0.8,$S$8, E67>= 0.75,$S$9, E67 >= 0.7, $S$10, E67>= 0.65, $S$11, E67>= 0.6, $S$12, E67>= 0.55,$S$13, E67 >= 0.5,$S$14)} -> 0.75
A34: Indiana State | B34: Charlotte | C34: -3 | D34: FALSE | E34: 0.55 | F34: 108.3 | G34: 109.6 | H34: 68.7 | I34: 105.2 | J34: 110.4 | K34: 74.3 | L34: 3.86 | N34: 45964 | O34: {=_xlfn.IFS(E68>=0.99,$S$3, E68>=0.95,$S$4, E68>= 0.93, $S$5, E68>= 0.9,$S$6, E68>= 0.85,$S$7, E68>= 0.8,$S$8, E68>= 0.75,$S$9, E68 >= 0.7, $S$10, E68>= 0.65, $S$11, E68>= 0.6, $S$12, E68>= 0.55,$S$13, E68 >= 0.5,$S$14)} -> 0.33333333
A35: Southern Miss | B35: Buffalo | C35: -1.5 | D35: FALSE | E35: 0.54 | F35: 101.5 | G35: 113.8 | H35: 72.1 | I35: 102.4 | J35: 111.3 | K35: 71.8 | L35: -3.36 | N35: 45964 | O35: {=_xlfn.IFS(E69>=0.99,$S$3, E69>=0.95,$S$4, E69>= 0.93, $S$5, E69>= 0.9,$S$6, E69>= 0.85,$S$7, E69>= 0.8,$S$8, E69>= 0.75,$S$9, E69 >= 0.7, $S$10, E69>= 0.65, $S$11, E69>= 0.6, $S$12, E69>= 0.55,$S$13, E69 >= 0.5,$S$14)} -> 0.33333333
A36: Iowa | B36: Nebraska | C36: -7.5 | D36: TRUE | E36: 0.965 | F36: 114.2 | G36: 98.2 | H36: 67.7 | I36: 117.9 | J36: 106.8 | K36: 70 | L36: 4.91 | M36: N | N36: 45725 | O36: {=_xlfn.IFS(E70>=0.99,$S$3, E70>=0.95,$S$4, E70>= 0.93, $S$5, E70>= 0.9,$S$6, E70>= 0.85,$S$7, E70>= 0.8,$S$8, E70>= 0.75,$S$9, E70 >= 0.7, $S$10, E70>= 0.65, $S$11, E70>= 0.6, $S$12, E70>= 0.55,$S$13, E70 >= 0.5,$S$14)} -> 0.56666667
A37: Utah | B37: BYU | C37: -11.5 | D37: TRUE | E37: 1 | F37: 123.1 | G37: 100.2 | H37: 67.3 | I37: 113.4 | J37: 102 | K37: 68.9 | L37: 11.47 | M37: N | N37: 45724 | O37: {=_xlfn.IFS(E71>=0.99,$S$3, E71>=0.95,$S$4, E71>= 0.93, $S$5, E71>= 0.9,$S$6, E71>= 0.85,$S$7, E71>= 0.8,$S$8, E71>= 0.75,$S$9, E71 >= 0.7, $S$10, E71>= 0.65, $S$11, E71>= 0.6, $S$12, E71>= 0.55,$S$13, E71 >= 0.5,$S$14)} -> 0.56666667
A38: Virginia Tech | B38: Clemson | C38: -17.5 | D38: TRUE | E38: 1 | F38: 120.9 | G38: 96.3 | H38: 64.1 | I38: 107.8 | J38: 107.3 | K38: 65.4 | L38: 24.13 | M38: Y | N38: 45724 | O38: {=_xlfn.IFS(E72>=0.99,$S$3, E72>=0.95,$S$4, E72>= 0.93, $S$5, E72>= 0.9,$S$6, E72>= 0.85,$S$7, E72>= 0.8,$S$8, E72>= 0.75,$S$9, E72 >= 0.7, $S$10, E72>= 0.65, $S$11, E72>= 0.6, $S$12, E72>= 0.55,$S$13, E72 >= 0.5,$S$14)} -> 0.5
A39: Stanford | B39: Louisville | C39: -11.5 | D39: TRUE | E39: 0.9975 | F39: 118.8 | G39: 96.3 | H39: 69.2 | I39: 112.8 | J39: 103.5 | K39: 66.8 | L39: 13.22 | M39: Y | N39: 45724 | O39: {=_xlfn.IFS(E73>=0.99,$S$3, E73>=0.95,$S$4, E73>= 0.93, $S$5, E73>= 0.9,$S$6, E73>= 0.85,$S$7, E73>= 0.8,$S$8, E73>= 0.75,$S$9, E73 >= 0.7, $S$10, E73>= 0.65, $S$11, E73>= 0.6, $S$12, E73>= 0.55,$S$13, E73 >= 0.5,$S$14)} -> 0.61538462
A40: Providence | B40: Xavier | C40: -12 | D40: TRUE | E40: 0.9975 | F40: 114.7 | G40: 98 | H40: 69.2 | I40: 112.9 | J40: 105.1 | K40: 66.6 | L40: 8.89 | M40: N | N40: 45724 | O40: {=_xlfn.IFS(E74 = 1, $S$2, E74>=0.99,$S$3, E74>=0.95,$S$4, E74>= 0.93, $S$5, E74>= 0.9,$S$6, E74>= 0.85,$S$7, E74>= 0.8,$S$8, E74>= 0.75,$S$9, E74 >= 0.7, $S$10, E74>= 0.65, $S$11, E74>= 0.6, $S$12, E74>= 0.55,$S$13, E74 >= 0.5,$S$14)} -> 0.5
...

Sheet recent
A1: CI LEVEL | B1: RECORD | C1: SUCCESS RATE | D1: LAST 10 DAYS | E1: UNITS | F1: RETURN
A2: 1 | B2: 25-27 | C2: 0.48076923 | D2: 16-25 | E2: 5 | F2: -23.5
A3: 99-99.9% | B3: 28-41 | C3: 0.4057971 | D3: 17-29 | E3: 0.5 | F3: -8.55
A4: 95-99% | B4: 21-27 | C4: 0.4375 | D4: 14-20 | E4: 0.5 | F4: -2.85
A5: 93-95% | B5: 4-3 | C5: 0.57142857 | D5: 3-1 | E5: 1 | F5: 0.7
A6: 90-93% | B6: 2-4 | C6: 0.33333333 | D6: 2-4 | E6: 2.5 | F6: -6
A7: 85-90% | B7: 6-10 | C7: 0.375 | D7: 3-9 | E7: 2.5 | F7: -16.5
A8: 80-85% | B8: 2-3 | C8: 0.4 | D8: 2-2 | E8: 0.5 | F8: -0.65
A9: 75-80% | B9: 4-5 | C9: 0.44444444 | D9: 1-4 | E9: 1.5 | F9: -2.25
A10: 70-75% | B10: 2-3 | C10: 0.4 | D10: 1-2 | E10: 0.5 | F10: -0.65
A11: 65-70% | B11: 4-5 | C11: 0.44444444 | D11: 3-2 | E11: 2.5 | F11: -3.75
A12: 60-65% | B12: 7-3 | C12: 0.7 | D12: 5-1 | E12: 0.5 | F12: 1.85
A13: 55-60% | B13: 3-4 | C13: 0.42857143 | D13: 3-2 | E13: 2 | F13: -2.8
A14: 50-55% | B14: 3-4 | C14: 0.42857143 | D14: 3-2 | E14: 0.5 | F14: -0.7
